<?xml version="1.0"?>
<robot name = "my_snake_robot">

	<gazebo>
  		<plugin name="gazebo_ros_control" filename="libgazebo_ros_control.so">
    			<robotNamespace>/my_snake_robot</robotNamespace>
  		</plugin>
	</gazebo>

	<material name = "black">
		<color rgba = "0 0 0 1"/>
	</material>
	<material name = "grey">
		<color rgba = "0.75 0.75 0.75 1"/>
	</material>
  
  	<gazebo reference = "base_link">
  		<kp>1000</kp>
  		<kd>10</kd>
  		<mu1>10</mu1>
  		<mu2>10</mu2>
  	</gazebo>

    <link name = "dummy_link">
      <visual>
        <origin rpy="0 0 0" xyz="0 0 0"/>
      </visual>
    </link>

    <joint name = "dummy" type="fixed">
      <parent link = "dummy_link"/>
      <child link = "base_link"/>
      <origin xyz="0 -0.01 0" rpy="0 0 0"/>
    </joint>

    <link name="base_link">
		<inertial>
			<origin xyz = "0 0 0" rpy = "0 0 0"/>
			<mass value = "0.00546"/>
			<inertia ixx ="1.8655e-04" ixy="0" ixz= "0"
			 iyy= "1.193e-04" iyz="0" izz="1.603e-04"/>
		</inertial>
        <collision>
            <origin xyz="0 0 0" rpy="0 0 0"/>
            <geometry>
				<box size = "0.032 0.03 0.04"/>
			</geometry>
        </collision>		
		<visual>
			<origin rpy="0 0 0" xyz="0 0 0"/>
			<geometry>
				<box size = "0.032 0.05 0.04"/>
			</geometry>
			<material name="black"/>
		</visual>
    </link>
  
  	<gazebo reference = "actuating0">
  		<kp>1000</kp>
  		<kd>10</kd>
  		<mu1>10</mu1>
  		<mu2>10</mu2>
  	</gazebo>

    <link name="actuating0">
    		<inertial>
			<origin xyz = "0 0 0" rpy = "0 1.57 0"/>
			<mass value = "0.00546"/>
			<inertia ixx ="1.703e-05" ixy="0" ixz= "0"
			 iyy= "1.703e-04" iyz="0" izz="6.05e-06"/>
		</inertial>
        <collision>
            <origin xyz="0 0 0" rpy="0 0 0"/>
            <geometry>
                <cylinder radius="0.011" length="0.041"/>
			</geometry>
        </collision>		
        <visual>
            <origin rpy="0 1.57 0" xyz="0 0 0"/>
            <geometry>
                <cylinder radius="0.011" length="0.041"/>
            </geometry>
            <material name="black"/>
        </visual>
    </link>
     
    <joint name="joint0" type="revolute">
        <parent link="base_link"/>
        <child link="actuating0"/>
        <origin xyz="0 -0.01 0" rpy="0 0 0"/>
        <limit lower="-0.523" upper="0.523" effort="0.1" velocity="0.005"/>
        <axis xyz="1 0 0"/>
    </joint>
  	
  	<transmission name = "tran0">
  		<type>transmission_interface/SimpleTransmission</type>
  		<joint name = "joint0">
  			<hardwareInterface>EffortJointInterface</hardwareInterface>
  		</joint>
  		<actuator name="motor0">
  			<hardwareInterface>EffortJointInterface</hardwareInterface>
  			<mechanicalReduction>1</mechanicalReduction>
  		</actuator>
  	</transmission>

  	<gazebo reference = "motor1">
  		<kp>1000</kp>
  		<kd>10</kd>
  		<mu1>10</mu1>
  		<mu2>10</mu2>
  	</gazebo>

    <link name="motor1">
		<inertial>
			<origin xyz = "0 0 0" rpy = "0 0 0"/>
			<mass value = "0.00546"/>
			<inertia ixx ="1.8655e-04" ixy="0" ixz= "0"
			 iyy= "1.193e-04" iyz="0" izz="1.603e-04"/>
		</inertial>
        <collision>
            <origin xyz="0 0 0" rpy="0 0 0"/>
            <geometry>
				<box size = "0.032 0.03 0.04"/>
			</geometry>
        </collision>		
		<visual>
			<origin rpy="0 1.57 0" xyz="0 0 0"/>
			<geometry>
				<box size = "0.032 0.05 0.04"/>
			</geometry>
			<material name="black"/>
		</visual>
	</link>

	<joint name= "fixed_1" type = "fixed">
		<parent link = "actuating0"/>
		<child link = "motor1"/>
		<origin xyz = "0 -0.045 0" rpy="0 0 0"/>
		<axis xyz= "1 0 0"/>
	</joint>

  	<gazebo reference = "actuating1">
  		<kp>1000</kp>
  		<kd>10</kd>
  		<mu1>10</mu1>
  		<mu2>10</mu2>
  	</gazebo>
	
	<link name="actuating1">
    		<inertial>
			<origin xyz = "0 0 0" rpy = "0 1.57 0"/>
			<mass value = "0.00546"/>
			<inertia ixx ="1.703e-04" ixy="0" ixz= "0"
			 iyy= "1.703e-04" iyz="0" izz="6.05e-05"/>
		</inertial>
        <collision>
            <origin xyz="0 0 0" rpy="0 0 0"/>
            <geometry>
                <cylinder radius="0.011" length="0.041"/>
			</geometry>
        </collision>	
        <visual>
            <origin rpy="0 0 0" xyz="0 0 0"/>
            <geometry>
                <cylinder radius="0.011" length="0.041"/>

            </geometry>
            <material name="black"/>
        </visual>

    </link>
    
    <joint name="joint1" type="revolute">
        <parent link="motor1"/>
        <child link="actuating1"/>
        <origin xyz="0 -0.01 0" rpy="0 0 0"/>
        <limit lower="-0.523" upper="0.523" effort="0.1" velocity="0.005"/>
        <axis xyz="0 0 1"/>
    </joint>

</robot>